<?xml version="1.0" ?>
<!-- =================================================================================== -->
<!-- |    This document was autogenerated by xacro from ./queenie/src/urdf/queenie.xacro | -->
<!-- |    EDITING THIS FILE BY HAND IS NOT RECOMMENDED                                 | -->
<!-- =================================================================================== -->
<robot name="queenie">

  <transmission name="neck_trans" type="SimpleTransmission">
    <type>transmission_interface/SimpleTransmission</type>
    <actuator name="neck_trans">
      <mechanicalReduction>1</mechanicalReduction>
    </actuator>
    <joint name="neck">
      <hardwareInterface>hardware_interface/EffortJointInterface</hardwareInterface>
    </joint>
  </transmission>
  <transmission name="neck_x_trans" type="SimpleTransmission">
    <type>transmission_interface/SimpleTransmission</type>
    <actuator name="neck_x_trans">
      <mechanicalReduction>1</mechanicalReduction>
    </actuator>
    <joint name="neck_x">
      <hardwareInterface>hardware_interface/EffortJointInterface</hardwareInterface>
    </joint>
  </transmission>

  <transmission name="palm_left_finger_trans" type="SimpleTransmission">
    <type>transmission_interface/SimpleTransmission</type>
    <actuator name="palm_left_finger_trans">
      <mechanicalReduction>1</mechanicalReduction>
    </actuator>
    <joint name="palm_left_finger">
      <hardwareInterface>hardware_interface/EffortJointInterface</hardwareInterface>
    </joint>
  </transmission>
  <transmission name="palm_right_finger_trans" type="SimpleTransmission">
    <type>transmission_interface/SimpleTransmission</type>
    <actuator name="palm_right_finger_trans">
      <mechanicalReduction>1</mechanicalReduction>
    </actuator>
    <joint name="palm_right_finger">
      <hardwareInterface>hardware_interface/EffortJointInterface</hardwareInterface>
    </joint>
  </transmission>
  <!-- <xacro:include filename="$(find queenie)/urdf/queenie.trans"  /> -->
  
  <link name="chassis">
    <inertial>
      <origin rpy="0 0 0" xyz="0 0 0.05"/>
      <mass value="15"/>
      <inertia ixx="0.284375" ixy="0.0" ixz="0.0" iyy="0.284375" iyz="0.0" izz="0.46875"/>
    </inertial>
    <collision name="collision">
      <origin rpy=" 0 0 0" xyz="0 0 0.05"/>
      <geometry>
        <cylinder length="0.2" radius="0.25"/>
      </geometry>
    </collision>
    <visual name="chassis_visual">
      <origin rpy=" 0 0 0" xyz="0 0 0.05"/>
      <geometry>
        <cylinder length="0.2" radius="0.25"/>
      </geometry>
    </visual>
  </link>
  <joint name="gripper_extension" type="fixed">
    <parent link="chassis"/>
    <child link="gripper_pole"/>
    <!-- <limit effort="1000.0" lower="-0.13" upper="0" velocity="0.05"/> -->
    <origin rpy="0 0 0" xyz="0.30 0 0.05"/>
  </joint>
  <link name="gripper_pole">
    <visual>
      <geometry>
        <box size="0.1 0.05 0.05"/>
      </geometry>
      <origin rpy="0 0 0 " xyz="0 0 0"/>
    </visual>
    <collision>
      <geometry>
        <box size="0.01 0.05 0.05"/>
      </geometry>
      <origin rpy="0 0 0 " xyz="0 0 0"/>
    </collision>
    <inertial>
      <!-- <xacro:insert_block name="origin"/> -->
      <origin rpy="0 0 0" xyz="0 0 0"/>
      <mass value="0.5"/>
      <inertia ixx="0.00020833333333333337" ixy="0.0" ixz="0.0" iyy="0.00020833333333333337" iyz="0.0" izz="0.00020833333333333337"/>
    </inertial>
  </link>
  <joint name="neck" type="revolute">
    <parent link="gripper_pole"/>
    <child link="head"/>
    <limit effort="1000.0" lower="-1.0471975511965976" upper="0.22" velocity="0.05"/>
    <origin rpy="0 0 0" xyz="0.0 0 0"/>
    <axis xyz="0 1 0"/>
    <dynamics damping="0.1" friction="0.1"/>
  </joint>
  <link name="head">
    <inertial>
      <!-- <xacro:insert_block name="origin"/> -->
      <origin rpy="0 0 0" xyz="0.0 0 0"/>
      <mass value="0.8"/>
      <inertia ixx="4.333333333333334e-05" ixy="0.0" ixz="0.0" iyy="8.333333333333334e-06" iyz="0.0" izz="4.833333333333335e-05"/>
    </inertial>
    <!-- <visual><geometry><sphere radius=".01"/></geometry></visual> -->
  </link>
  <joint name="neck_x" type="revolute">
    <parent link="head"/>
    <child link="head_x"/>
    <limit effort="4" lower="-0.5" upper="0.5" velocity="0.05"/>
    <origin rpy="0 0 0" xyz="0.0 0 0"/>
    <axis xyz="1 0 0"/>
    <dynamics damping="0.1" friction="0.1"/>
  </joint>
  <link name="head_x">
    <inertial>
      <!-- <xacro:insert_block name="origin"/> -->
      <origin rpy="0 0 0" xyz="0.0 0 0"/>
      <mass value="0.8"/>
      <inertia ixx="4.333333333333334e-05" ixy="0.0" ixz="0.0" iyy="8.333333333333334e-06" iyz="0.0" izz="4.833333333333335e-05"/>
    </inertial>
    <!-- <visual><geometry><sphere radius=".01"/></geometry></visual> -->
  </link>
  <joint name="head_gripper_pole_vertical" type="fixed">
    <parent link="head_x"/>
    <child link="palm"/>
    <!-- <limit effort="1000.0" lower="-0.13" upper="0" velocity="0.5"/> -->
    <origin rpy="0 0 0" xyz="0.05 0 0"/>
  </joint>
  <link name="palm">
    <collision name="palm_collision">
      <geometry>
        <box size="0.05 0.25 0.05"/>
      </geometry>
      <origin rpy="0 0 0 " xyz="0.025 0 0"/>
    </collision>
    <visual name="visual">
      <geometry>
        <box size="0.05 0.25 0.05"/>
      </geometry>
      <origin rpy="0 0 0 " xyz="0.025 0 0"/>
    </visual>
    <inertial>
      <!-- <xacro:insert_block name="origin"/> -->
      <origin rpy="0 0 0" xyz="0.025 0 0"/>
      <mass value="0.8"/>
      <inertia ixx="0.004333333333333333" ixy="0.0" ixz="0.0" iyy="0.0003333333333333334" iyz="0.0" izz="0.004333333333333333"/>
    </inertial>
  </link>
  <joint name="palm_left_finger" type="prismatic">
    <child link="left_finger"/>
    <parent link="palm"/>
    <limit effort="1000.0" lower="0" upper="0.1" velocity="0.5"/>
    <origin rpy="0 0 0" xyz="0.125 0.025 0"/>
    <axis xyz="0 1 0"/>
    <dynamics damping="0" friction="0.1"/>
  </joint>
  <link name="left_finger">
    <contact>
      <lateral_friction value="1"/>
      <rolling_friction value="0.0"/>
      <stiffness value="300000"/>
      <damping value="1000"/>
    </contact>
    <collision name="left_finger_collision">
      <geometry>
        <box size="0.15 0.05 0.05"/>
      </geometry>
      <origin rpy="0 0 0 " xyz="0 0 0"/>
    </collision>
    <visual name="visual">
      <geometry>
        <box size="0.15 0.05 0.05"/>
      </geometry>
      <origin rpy="0 0 0 " xyz="0 0 0"/>
    </visual>
    <inertial>
      <!-- <xacro:insert_block name="origin"/> -->
      <origin rpy="0 0 0" xyz="0 0 0"/>
      <mass value="0.3"/>
      <inertia ixx="0.000125" ixy="0.0" ixz="0.0" iyy="0.000625" iyz="0.0" izz="0.000625"/>
    </inertial>
  </link>
  <joint name="palm_right_finger" type="prismatic">
    <child link="right_finger"/>
    <parent link="palm"/>
    <limit effort="1000.0" lower="0" upper="0.1" velocity="0.5"/>
    <origin rpy="0 0 0" xyz="0.125 -0.025 0"/>
    <axis xyz="0 -1 0"/>
    <dynamics damping="0" friction="0.1"/>
  </joint>
  <link name="right_finger">
    <contact>
      <lateral_friction value="1"/>
      <rolling_friction value="0"/>
      <stiffness value="300000"/>
      <damping value="1000"/>
    </contact>
    <collision name="right_finger_collision">
      <geometry>
        <box size="0.15 0.05 0.05"/>
      </geometry>
      <origin rpy="0 0 0 " xyz="0 0 0"/>
    </collision>
    <visual name="visual">
      <geometry>
        <box size="0.15 0.05 0.05"/>
      </geometry>
      <origin rpy="0 0 0 " xyz="0 0 0"/>
    </visual>
    <inertial>
      <!-- <xacro:insert_block name="origin"/> -->
      <origin rpy="0 0 0" xyz="0 0 0"/>
      <mass value="0.3"/>
      <inertia ixx="0.000125" ixy="0.0" ixz="0.0" iyy="0.000625" iyz="0.0" izz="0.000625"/>
    </inertial>
  </link>
  <joint name="left_wheel_hinge" type="continuous">
    <origin rpy="0 0 0" xyz="0.15 0.30 0"/>
    <parent link="chassis"/>
    <child link="left_wheel"/>
    <axis rpy="0 0 0" xyz="0 1 0"/>
    <limit effort="1000" velocity="1000"/>
    <dynamics damping="0.0" friction="0.0"/>
  </joint>
  <link name="left_wheel">
    <contact>
      <lateral_friction value=".8"/>
      <rolling_friction value="0.0"/>
      <stiffness value="300000"/>
      <damping value="1000"/>
    </contact>
    <inertial>
      <origin rpy="0 1.5707963267948966 1.5707963267948966" xyz="0 0 0"/>
      <mass value="2"/>
      <inertia ixx="0.005416666666666668" ixy="0.0" ixz="0.0" iyy="0.005416666666666668" iyz="0.0" izz="0.010000000000000002"/>
    </inertial>
    <collision>
      <origin rpy="0 1.5707 1.5707" xyz="0 0 0"/>
      <geometry>
        <cylinder length="0.05" radius="0.1"/>
      </geometry>
    </collision>
    <visual>
      <origin rpy="0 1.5707 1.5707" xyz="0 0 0"/>
      <geometry>
        <cylinder length="0.05" radius="0.1"/>
      </geometry>
    </visual>
  </link>
  <joint name="right_wheel_hinge" type="continuous">
    <origin rpy="0 0 0" xyz="0.15 -0.30 0"/>
    <parent link="chassis"/>
    <child link="right_wheel"/>
    <axis rpy="0 0 0" xyz="0 1 0"/>
    <limit effort="1000" velocity="1000"/>
    <dynamics damping="0.0" friction="0.0"/>
  </joint>
  <link name="right_wheel">
    <contact>
      <lateral_friction value=".8"/>
      <rolling_friction value="0.0"/>
      <stiffness value="300000"/>
      <damping value="1000"/>
    </contact>
    <inertial>
      <origin rpy="0 1.5707963267948966 1.5707963267948966" xyz="0 0 0"/>
      <mass value="2"/>
      <inertia ixx="0.005416666666666668" ixy="0.0" ixz="0.0" iyy="0.005416666666666668" iyz="0.0" izz="0.010000000000000002"/>
    </inertial>
    <collision>
      <origin rpy="0 1.5707 1.5707" xyz="0 0 0"/>
      <geometry>
        <cylinder length="0.05" radius="0.1"/>
      </geometry>
    </collision>
    <visual>
      <origin rpy="0 1.5707 1.5707" xyz="0 0 0"/>
      <geometry>
        <cylinder length="0.05" radius="0.1"/>
      </geometry>
    </visual>
  </link>
  <joint name="left_wheel_back_hinge" type="continuous">
    <origin rpy="0 0 0" xyz="-0.15 0.30 0"/>
    <parent link="chassis"/>
    <child link="left_wheel_back"/>
    <axis rpy="0 0 0" xyz="0 1 0"/>
    <limit effort="1000" velocity="1000"/>
    <dynamics damping="0.0" friction="0.0"/>
  </joint>
  <link name="left_wheel_back">
    <contact>
      <lateral_friction value=".8"/>
      <rolling_friction value="0.0"/>
      <stiffness value="300000"/>
      <damping value="1000"/>
    </contact>
    <inertial>
      <origin rpy="0 1.5707963267948966 1.5707963267948966" xyz="0 0 0"/>
      <mass value="2"/>
      <inertia ixx="0.005416666666666668" ixy="0.0" ixz="0.0" iyy="0.005416666666666668" iyz="0.0" izz="0.010000000000000002"/>
    </inertial>
    <collision>
      <origin rpy="0 1.5707 1.5707" xyz="0 0 0"/>
      <geometry>
        <cylinder length="0.05" radius="0.1"/>
      </geometry>
    </collision>
    <visual>
      <origin rpy="0 1.5707 1.5707" xyz="0 0 0"/>
      <geometry>
        <cylinder length="0.05" radius="0.1"/>
      </geometry>
    </visual>
  </link>
  <joint name="right_wheel_back_hinge" type="continuous">
    <origin rpy="0 0 0" xyz="-0.15 -0.30 0"/>
    <parent link="chassis"/>
    <child link="right_wheel_back"/>
    <axis rpy="0 0 0" xyz="0 1 0"/>
    <limit effort="1000" velocity="1000"/>
    <dynamics damping="0.0" friction="0.0"/>
  </joint>
  <link name="right_wheel_back">
    <contact>
      <lateral_friction value=".8"/>
      <rolling_friction value="0.0"/>
      <stiffness value="300000"/>
      <damping value="1000"/>
    </contact>
    <inertial>
      <origin rpy="0 1.5707963267948966 1.5707963267948966" xyz="0 0 0"/>
      <mass value="2"/>
      <inertia ixx="0.005416666666666668" ixy="0.0" ixz="0.0" iyy="0.005416666666666668" iyz="0.0" izz="0.010000000000000002"/>
    </inertial>
    <collision>
      <origin rpy="0 1.5707 1.5707" xyz="0 0 0"/>
      <geometry>
        <cylinder length="0.05" radius="0.1"/>
      </geometry>
    </collision>
    <visual>
      <origin rpy="0 1.5707 1.5707" xyz="0 0 0"/>
      <geometry>
        <cylinder length="0.05" radius="0.1"/>
      </geometry>
    </visual>
  </link>
  <joint name="camera_joint" type="fixed">
    <origin rpy="0 0 0" xyz="0.025 0 0.05"/>
    <parent link="palm"/>
    <child link="camera"/>
    <axis xyz="0 0 1"/>
  </joint>
  <link name="camera">
    <inertial>
      <!-- <xacro:insert_block name="origin"/> -->
      <origin rpy="0 0 0" xyz="0 0 0"/>
      <mass value="0.01"/>
      <inertia ixx="4.166666666666667e-06" ixy="0.0" ixz="0.0" iyy="4.166666666666667e-06" iyz="0.0" izz="4.166666666666667e-06"/>
    </inertial>
    <visual>
      <origin rpy="0 0 0" xyz="0 0 0"/>
      <geometry>
        <box size="0.05 0.05 0.05"/>
      </geometry>
    </visual>
  </link>
  <joint name="camera_optical_joint" type="fixed">
    <parent link="camera"/>
    <child link="camera_optical"/>
    <origin rpy="-1.5707963267948966 0.0 -1.5707963267948966" xyz="0.0 0.0 0.0"/>
  </joint>
  <link name="camera_optical"/>
</robot>

